<?xml version="1.0"?>
<robot xmlns:xacro="http://www.ros.org/wiki/xacro">

    <xacro:include filename="inertial_macros.xacro"/>

    <material name="white"><color rgba="1 1 1 1"/></material>
    <material name="orange"><color rgba="1 0.3 0.1 1"/></material>
    <material name="blue"><color rgba="0.2 0.2 1 1"/></material>
    <material name="black"><color rgba="0 0 0 1"/></material>

    <link name="base_link"></link>

    <joint name="base_footprint_joint" type="fixed">
        <parent link="base_link"/>
        <child link="base_footprint"/>
        <origin xyz="0 0 0" rpy="0 0 0"/>
    </joint>

    <link name="base_footprint"></link>


    <joint name="chassis_joint" type="fixed">
        <parent link="base_link"/>
        <child link="chassis_link"/>
        <!-- <origin xyz="-0.1 0 0"/> -->
        <origin xyz="-0.1 0 0"/>
    </joint>

    <link name="chassis_link">
        <visual>
            <origin xyz="0.3 0 0.075"/>
            <geometry>
                <box size="0.6 0.3 0.15"/>
            </geometry>
            <material name="white"/>
        </visual>
        <collision>
            <origin xyz="0.3 0 0.075"/>
            <geometry>
                <box size="0.6 0.3 0.15"/>
            </geometry>
        </collision>
        <xacro:inertial_box mass="0.5" x="0.6" y="0.3" z="0.15">
            <origin xyz="0.3 0 0.075" rpy="0 0 0"/>
        </xacro:inertial_box>
    </link>

    <joint name="front_left_wheel_joint" type="continuous">
        <parent link="chassis_link"/>
        <child link="front_left_wheel_link"/>
        <!-- <origin xyz="0 0.170 0" rpy="${-pi/2} 0 0"/> -->
        <!-- <origin xyz="0.2 0.170 0" rpy="${-pi/2} 0 0"/> -->
        <origin xyz="0.5 0.170 0" rpy="${-pi/2} 0 0"/>
        <axis xyz="0 0 1"/>
    </joint>

    <link name="front_left_wheel_link">
        <visual>
            <geometry>
                <cylinder length="0.03" radius="0.1"/>
            </geometry>
            <material name="blue"/>
        </visual>
        <collision>
            <geometry>
                <sphere radius="0.1"/>
            </geometry>
        </collision>
        <xacro:inertial_cylinder mass="0.1" length="0.03" radius="0.1">
            <origin xyz="0 0 0" rpy="0 0 0"/>
        </xacro:inertial_cylinder>
    </link>


    <joint name="front_right_wheel_joint" type="continuous">
        <parent link="chassis_link"/>
        <child link="front_right_wheel_link"/>
        <!-- <origin xyz="0 -0.170 0" rpy="${pi/2} 0 0"/> -->
        <!-- <origin xyz="0.2 -0.170 0" rpy="${pi/2} 0 0"/> -->
        <origin xyz="0.5 -0.170 0" rpy="${pi/2} 0 0"/>
        <axis xyz="0 0 -1"/>
    </joint>

    <link name="front_right_wheel_link">
        <visual>
            <geometry>
                <cylinder length="0.03" radius="0.1"/>
            </geometry>
            <material name="blue"/>
        </visual>
        <collision>
            <geometry>
                <sphere radius="0.1"/>
            </geometry>
        </collision>
        <xacro:inertial_cylinder mass="0.1" length="0.03" radius="0.1">
            <origin xyz="0 0 0" rpy="0 0 0"/>
        </xacro:inertial_cylinder>
    </link>

    <joint name="rear_left_wheel_joint" type="continuous">
        <parent link="chassis_link"/>
        <child link="rear_left_wheel_link"/>
        <!-- <origin xyz="0 0.170 0" rpy="${-pi/2} 0 0"/> -->
        <!-- <origin xyz="-0.2 0.170 0" rpy="${-pi/2} 0 0"/> -->
        <origin xyz="0.1 0.170 0" rpy="${-pi/2} 0 0"/>
        <axis xyz="0 0 1"/>
    </joint>

    <link name="rear_left_wheel_link">
        <visual>
            <geometry>
                <cylinder length="0.03" radius="0.1"/>
            </geometry>
            <material name="blue"/>
        </visual>
        <collision>
            <geometry>
                <sphere radius="0.1"/>
            </geometry>
        </collision>
        <xacro:inertial_cylinder mass="0.1" length="0.03" radius="0.1">
            <origin xyz="0 0 0" rpy="0 0 0"/>
        </xacro:inertial_cylinder>
    </link>


    <joint name="rear_right_wheel_joint" type="continuous">
        <parent link="chassis_link"/>
        <child link="rear_right_wheel_link"/>
        <!-- <origin xyz="0 -0.170 0" rpy="${pi/2} 0 0"/> -->
        <!-- <origin xyz="-0.2 -0.170 0" rpy="${pi/2} 0 0"/> -->
        <origin xyz="0.1 -0.170 0" rpy="${pi/2} 0 0"/>
        <axis xyz="0 0 -1"/>
    </joint>

    <link name="rear_right_wheel_link">
        <visual>
            <geometry>
                <cylinder length="0.03" radius="0.1"/>
            </geometry>
            <material name="blue"/>
        </visual>
        <collision>
            <geometry>
                <sphere radius="0.1"/>
            </geometry>
        </collision>
        <xacro:inertial_cylinder mass="0.1" length="0.03" radius="0.1">
            <origin xyz="0 0 0" rpy="0 0 0"/>
        </xacro:inertial_cylinder>
    </link>

    <joint name="caster_wheel_joint" type="fixed">
        <parent link="chassis_link"/>
        <child link="caster_wheel_link"/>
        <!-- <origin xyz="0.45 0 -0.05" rpy="0 0 0"/> -->
        <!-- <origin xyz="0.25 0 -0.05" rpy="0 0 0"/> -->
        <origin xyz="0.55 0 -0.05" rpy="0 0 0"/>
    </joint>

    <link name="caster_wheel_link">
        <visual>
            <geometry>
                <sphere radius="0.05"/>
            </geometry>
            <material name="black"/>
        </visual>
        <xacro:inertial_sphere mass="0.1" radius="0.05">
            <origin xyz="0.45 0 -0.05" rpy="0 0 0"/>
        </xacro:inertial_sphere>
    </link>


    <gazebo reference="chassis_link">
        <material>Gazebo/Orange</material>
    </gazebo>
    <gazebo reference="caster_wheel_link">
        <material>Gazebo/Black</material>
        <mu1 value="0.001"/>
        <mu2 value="0.001"/>
    </gazebo>
    <gazebo reference="front_left_wheel_link">
        <material>Gazebo/White</material>
        <mu1 value="0.001"/>
        <mu2 value="0.001"/>
    </gazebo>    
    <gazebo reference="front_right_wheel_link">
        <material>Gazebo/White</material>
        <mu1 value="0.001"/>
        <mu2 value="0.001"/>
    </gazebo>
</robot>
